2025-03-09 12:26:50,124 INFO    Thread-428 (_run_job):28684 [wandb_setup.py:_flush():67] Current SDK version is 0.19.8
2025-03-09 12:26:50,125 INFO    Thread-428 (_run_job):28684 [wandb_setup.py:_flush():67] Configure stats pid to 28684
2025-03-09 12:26:50,125 INFO    Thread-428 (_run_job):28684 [wandb_setup.py:_flush():67] Loading settings from C:\Users\arvin\.config\wandb\settings
2025-03-09 12:26:50,125 INFO    Thread-428 (_run_job):28684 [wandb_setup.py:_flush():67] Loading settings from c:\Users\arvin\Desktop\VSCode\DA6401- Deep Learning\wandb\settings
2025-03-09 12:26:50,125 INFO    Thread-428 (_run_job):28684 [wandb_setup.py:_flush():67] Loading settings from environment variables
2025-03-09 12:26:50,125 INFO    Thread-428 (_run_job):28684 [wandb_init.py:setup_run_log_directory():647] Logging user logs to c:\Users\arvin\Desktop\VSCode\DA6401- Deep Learning\wandb\run-20250309_122650-tey5k74h\logs\debug.log
2025-03-09 12:26:50,127 INFO    Thread-428 (_run_job):28684 [wandb_init.py:setup_run_log_directory():648] Logging internal logs to c:\Users\arvin\Desktop\VSCode\DA6401- Deep Learning\wandb\run-20250309_122650-tey5k74h\logs\debug-internal.log
2025-03-09 12:26:50,127 INFO    Thread-428 (_run_job):28684 [wandb_init.py:monkeypatch_ipython():599] configuring jupyter hooks <wandb.sdk.wandb_init._WandbInit object at 0x000002AC30F92FE0>
2025-03-09 12:26:50,127 INFO    Thread-428 (_run_job):28684 [wandb_init.py:init():761] calling init triggers
2025-03-09 12:26:50,128 INFO    Thread-428 (_run_job):28684 [wandb_init.py:init():766] wandb.init called with sweep_config: {'activation': 'tanh', 'batch_size': 16, 'epochs': 10, 'hidden_layers': 5, 'hidden_size': 64, 'learning_rate': 0.001, 'optimizer': 'nesterov', 'weight_decay': 0.0005, 'weight_init': 'Xavier'}
config: {'_wandb': {}}
2025-03-09 12:26:50,128 INFO    Thread-428 (_run_job):28684 [wandb_init.py:init():784] starting backend
2025-03-09 12:26:50,128 INFO    Thread-428 (_run_job):28684 [wandb_init.py:init():788] sending inform_init request
2025-03-09 12:26:50,133 INFO    Thread-428 (_run_job):28684 [backend.py:_multiprocessing_setup():101] multiprocessing start_methods=spawn, using: spawn
2025-03-09 12:26:50,133 INFO    Thread-428 (_run_job):28684 [wandb_init.py:init():798] backend started and connected
2025-03-09 12:26:50,148 INFO    Thread-428 (_run_job):28684 [wandb_run.py:_config_callback():1261] config_cb None None {'activation': 'tanh', 'batch_size': 16, 'epochs': 10, 'hidden_layers': 5, 'hidden_size': 64, 'learning_rate': 0.001, 'optimizer': 'nesterov', 'weight_decay': 0.0005, 'weight_init': 'Xavier'}
2025-03-09 12:26:50,152 INFO    Thread-428 (_run_job):28684 [wandb_run.py:_label_probe_notebook():1204] probe notebook
2025-03-09 12:26:50,159 INFO    Thread-428 (_run_job):28684 [wandb_init.py:init():891] updated telemetry
2025-03-09 12:26:50,261 INFO    Thread-428 (_run_job):28684 [wandb_init.py:init():915] communicating run to backend with 90.0 second timeout
2025-03-09 12:26:50,917 INFO    Thread-428 (_run_job):28684 [wandb_init.py:init():990] starting run threads in backend
2025-03-09 12:26:51,942 INFO    Thread-428 (_run_job):28684 [wandb_run.py:_console_start():2375] atexit reg
2025-03-09 12:26:51,943 INFO    Thread-428 (_run_job):28684 [wandb_run.py:_redirect():2227] redirect: wrap_raw
2025-03-09 12:26:51,943 INFO    Thread-428 (_run_job):28684 [wandb_run.py:_redirect():2292] Wrapping output streams.
2025-03-09 12:26:51,943 INFO    Thread-428 (_run_job):28684 [wandb_run.py:_redirect():2315] Redirects installed.
2025-03-09 12:26:51,944 INFO    Thread-428 (_run_job):28684 [wandb_init.py:init():1032] run started, returning control to user process
2025-03-09 12:57:08,384 INFO    Thread-12 (_heartbeat):28684 [retry.py:__call__():175] Retry attempt failed:
Traceback (most recent call last):
  File "C:\Users\arvin\AppData\Roaming\Python\Python310\site-packages\urllib3\connection.py", line 174, in _new_conn
    conn = connection.create_connection(
  File "C:\Users\arvin\AppData\Roaming\Python\Python310\site-packages\urllib3\util\connection.py", line 72, in create_connection
    for res in socket.getaddrinfo(host, port, family, socket.SOCK_STREAM):
  File "c:\Users\arvin\Desktop\VSCode\DA6401- Deep Learning\.conda\lib\socket.py", line 967, in getaddrinfo
    for res in _socket.getaddrinfo(host, port, family, type, proto, flags):
socket.gaierror: [Errno 11001] getaddrinfo failed

During handling of the above exception, another exception occurred:

Traceback (most recent call last):
  File "C:\Users\arvin\AppData\Roaming\Python\Python310\site-packages\urllib3\connectionpool.py", line 715, in urlopen
    httplib_response = self._make_request(
  File "C:\Users\arvin\AppData\Roaming\Python\Python310\site-packages\urllib3\connectionpool.py", line 404, in _make_request
    self._validate_conn(conn)
  File "C:\Users\arvin\AppData\Roaming\Python\Python310\site-packages\urllib3\connectionpool.py", line 1058, in _validate_conn
    conn.connect()
  File "C:\Users\arvin\AppData\Roaming\Python\Python310\site-packages\urllib3\connection.py", line 363, in connect
    self.sock = conn = self._new_conn()
  File "C:\Users\arvin\AppData\Roaming\Python\Python310\site-packages\urllib3\connection.py", line 186, in _new_conn
    raise NewConnectionError(
urllib3.exceptions.NewConnectionError: <urllib3.connection.HTTPSConnection object at 0x000002AC3112B5E0>: Failed to establish a new connection: [Errno 11001] getaddrinfo failed

During handling of the above exception, another exception occurred:

Traceback (most recent call last):
  File "C:\Users\arvin\AppData\Roaming\Python\Python310\site-packages\requests\adapters.py", line 667, in send
    resp = conn.urlopen(
  File "C:\Users\arvin\AppData\Roaming\Python\Python310\site-packages\urllib3\connectionpool.py", line 799, in urlopen
    retries = retries.increment(
  File "C:\Users\arvin\AppData\Roaming\Python\Python310\site-packages\urllib3\util\retry.py", line 592, in increment
    raise MaxRetryError(_pool, url, error or ResponseError(cause))
urllib3.exceptions.MaxRetryError: HTTPSConnectionPool(host='api.wandb.ai', port=443): Max retries exceeded with url: /graphql (Caused by NewConnectionError('<urllib3.connection.HTTPSConnection object at 0x000002AC3112B5E0>: Failed to establish a new connection: [Errno 11001] getaddrinfo failed'))

During handling of the above exception, another exception occurred:

Traceback (most recent call last):
  File "c:\Users\arvin\Desktop\VSCode\DA6401- Deep Learning\.conda\lib\site-packages\wandb\sdk\lib\retry.py", line 134, in __call__
    result = self._call_fn(*args, **kwargs)
  File "c:\Users\arvin\Desktop\VSCode\DA6401- Deep Learning\.conda\lib\site-packages\wandb\sdk\internal\internal_api.py", line 398, in execute
    return self.client.execute(*args, **kwargs)  # type: ignore
  File "c:\Users\arvin\Desktop\VSCode\DA6401- Deep Learning\.conda\lib\site-packages\wandb\vendor\gql-0.2.0\wandb_gql\client.py", line 52, in execute
    result = self._get_result(document, *args, **kwargs)
  File "c:\Users\arvin\Desktop\VSCode\DA6401- Deep Learning\.conda\lib\site-packages\wandb\vendor\gql-0.2.0\wandb_gql\client.py", line 60, in _get_result
    return self.transport.execute(document, *args, **kwargs)
  File "c:\Users\arvin\Desktop\VSCode\DA6401- Deep Learning\.conda\lib\site-packages\wandb\sdk\lib\gql_request.py", line 58, in execute
    request = self.session.post(self.url, **post_args)
  File "C:\Users\arvin\AppData\Roaming\Python\Python310\site-packages\requests\sessions.py", line 637, in post
    return self.request("POST", url, data=data, json=json, **kwargs)
  File "C:\Users\arvin\AppData\Roaming\Python\Python310\site-packages\requests\sessions.py", line 589, in request
    resp = self.send(prep, **send_kwargs)
  File "C:\Users\arvin\AppData\Roaming\Python\Python310\site-packages\requests\sessions.py", line 703, in send
    r = adapter.send(request, **kwargs)
  File "C:\Users\arvin\AppData\Roaming\Python\Python310\site-packages\requests\adapters.py", line 700, in send
    raise ConnectionError(e, request=request)
requests.exceptions.ConnectionError: HTTPSConnectionPool(host='api.wandb.ai', port=443): Max retries exceeded with url: /graphql (Caused by NewConnectionError('<urllib3.connection.HTTPSConnection object at 0x000002AC3112B5E0>: Failed to establish a new connection: [Errno 11001] getaddrinfo failed'))
2025-03-09 12:58:19,454 INFO    Thread-428 (_run_job):28684 [wandb_run.py:_finish():2112] finishing run mm21b010-indian-institute-of-technology-madras/DL_A1/tey5k74h
2025-03-09 12:58:19,455 INFO    Thread-428 (_run_job):28684 [jupyter.py:save_history():458] not saving jupyter history
2025-03-09 12:58:19,455 INFO    Thread-428 (_run_job):28684 [jupyter.py:save_ipynb():386] not saving jupyter notebook
2025-03-09 12:58:19,455 INFO    Thread-428 (_run_job):28684 [wandb_init.py:_jupyter_teardown():581] cleaning up jupyter logic
2025-03-09 12:58:19,455 INFO    Thread-428 (_run_job):28684 [wandb_run.py:_atexit_cleanup():2340] got exitcode: 0
2025-03-09 12:58:19,456 INFO    Thread-428 (_run_job):28684 [wandb_run.py:_restore():2322] restore
2025-03-09 12:58:19,456 INFO    Thread-428 (_run_job):28684 [wandb_run.py:_restore():2328] restore done
2025-03-09 12:58:32,522 INFO    Thread-428 (_run_job):28684 [wandb_run.py:_footer_history_summary_info():3956] rendering history
2025-03-09 12:58:32,522 INFO    Thread-428 (_run_job):28684 [wandb_run.py:_footer_history_summary_info():3988] rendering summary
2025-03-09 12:58:32,525 INFO    Thread-428 (_run_job):28684 [wandb_run.py:_footer_sync_info():3917] logging synced files
